Workbook

Sheet Instrucciones
A1: Registro de validación · Release 2 · Antilia
A2: Formato de registro de docs/validacion/plan-release2.md (tareas) y docs/validacion/protocolo-release1.md (guion). Responsable: QA.
A4: Cómo usar este archivo
A5: Celdas amarillas | B5: Se diligencian a mano durante o después de cada sesión.
A6: Celdas azules | B6: Tienen fórmulas. No se escriben a mano.
A7: Filas grises «Ejemplo» | B7: Muestran el formato esperado. No se cuentan en los resultados porque su código no empieza por P.
A8: Códigos | B8: Cada participante usa un código P01, P02… igual en todas las hojas. El nombre real no se escribe en este archivo.
A9: Participantes | B9: Perfil, elegibilidad, consentimiento, modalidad, versión probada y enlace a la evidencia.
A10: Tareas | B10: Una fila por participante y tarea: resultado (Éxito o Fracaso), tiempo en segundos, errores y cita textual.
A11: SUS | B11: Las diez calificaciones de 1 a 5 de cada participante. El puntaje se calcula solo cuando las diez están completas.
A12: Hallazgos | B12: Problemas observados, ordenados por severidad (4 a 1) y frecuencia. Numerar H1, H2…
A13: Resumen | B13: Tasa de éxito por tarea, SUS promedio y si el release cumple el criterio de validación.
A14: Criterio de validación | B14: Cada tarea completada por al menos 4 de cada 5 participantes (80 %) y SUS promedio ≥ 68.
A16: Tareas (definidas en el plan del 25/10/2026)
A17: Tarea | B17: Texto leído · Criterio de éxito · Límite
A18: T1 | B18: «Cree un espacio para su escritorio y agréguele una cosa que tenga que ordenar hoy.» · Crea el espacio y una tarea asociada; al recargar, ambos siguen ahí · Límite: 120 s
A19: T2 | B19: «Planee cómo quiere su mesa: elija un modelo y ubique su portátil y sus libretas.» · Elige una mesa, coloca al menos dos tarjetas con nombre y guarda · Límite: 180 s
A20: T3 | B20: «Anote un correo que tenga pendiente por responder y márquelo como resuelto.» · Crea un correo pendiente en Correos y archivos y lo completa · Límite: 60 s
A21: T4 | B21: «Complete una de sus tareas y muéstreme cómo cambió Lumi.» · Completa una tarea y llega a la pantalla de racha con Lumi encendida · Límite: 45 s
A22: T5 | B22: «Escenario del hallazgo de mayor severidad del Release 1 con update (redactar el 26/10).» · Se cumple el criterio de terminado del update U01 o U02 · Límite: sin límite de tiempo
A24: Afirmaciones SUS (1 = totalmente en desacuerdo, 5 = totalmente de acuerdo)
A25: Q1 (impar: respuesta − 1) | B25: Creo que me gustaría usar esta aplicación con frecuencia.
A26: Q2 (par: 5 − respuesta) | B26: Encontré la aplicación innecesariamente compleja.
A27: Q3 (impar: respuesta − 1) | B27: Pensé que la aplicación era fácil de usar.
A28: Q4 (par: 5 − respuesta) | B28: Creo que necesitaría el apoyo de una persona experta para poder usar esta aplicación.
A29: Q5 (impar: respuesta − 1) | B29: Encontré que las funciones de la aplicación estaban bien integradas.
A30: Q6 (par: 5 − respuesta) | B30: Pensé que había demasiada inconsistencia en la aplicación.
A31: Q7 (impar: respuesta − 1) | B31: Imagino que la mayoría de las personas aprendería a usar esta aplicación muy rápidamente.
A32: Q8 (par: 5 − respuesta) | B32: Encontré la aplicación muy engorrosa de usar.
A33: Q9 (impar: respuesta − 1) | B33: Me sentí muy seguro o segura usando la aplicación.
A34: Q10 (par: 5 − respuesta) | B34: Necesité aprender muchas cosas antes de poder empezar a usar esta aplicación.
A35: Puntaje | B35: Suma de los diez valores ajustados × 2,5 (0 a 100). Por debajo de 51: problemas serios · 68: promedio de la industria · por encima de 80: excelente.
A37: Severidad de hallazgos
A38: 4 · Crítico | B38: Impide completar una tarea del recorrido principal
A39: 3 · Grave | B39: Se completa con mucha dificultad o fuera de tiempo, o afecta a dos o más participantes
A40: 2 · Moderado | B40: Causa duda o un error que el participante corrige solo
A41: 1 · Menor | B41: Problema de forma o texto que no afecta el resultado

Sheet Resumen
A1: Resumen de la validación del Release 2
A2: Todo se calcula a partir de las otras hojas. Solo se cuentan códigos que empiezan por P.
A4: Tarea | B4: Con resultado | C4: Éxitos | D4: Tasa de éxito | E4: Cumple ≥ 80 % | F4: Tiempo promedio (s)
A5: T1 · Crea el espacio y una tarea asociada; al recargar, ambos siguen ahí | B5: =COUNTIFS(Tareas!$A$6:$A$45,"P*",Tareas!$B$6:$B$45,"T1",Tareas!$D$6:$D$45,"?*") -> 0 | C5: =COUNTIFS(Tareas!$A$6:$A$45,"P*",Tareas!$B$6:$B$45,"T1",Tareas!$D$6:$D$45,"Éxito") -> 0 | D5: =IF(B5=0,"",C5/B5) | E5: =IF(B5=0,"",IF(D5>=0.8,"Sí","No")) | F5: =IFERROR(AVERAGEIFS(Tareas!$E$6:$E$45,Tareas!$A$6:$A$45,"P*",Tareas!$B$6:$B$45,"T1"),"")
A6: T2 · Elige una mesa, coloca al menos dos tarjetas con nombre y guarda | B6: =COUNTIFS(Tareas!$A$6:$A$45,"P*",Tareas!$B$6:$B$45,"T2",Tareas!$D$6:$D$45,"?*") -> 0 | C6: =COUNTIFS(Tareas!$A$6:$A$45,"P*",Tareas!$B$6:$B$45,"T2",Tareas!$D$6:$D$45,"Éxito") -> 0 | D6: =IF(B6=0,"",C6/B6) | E6: =IF(B6=0,"",IF(D6>=0.8,"Sí","No")) | F6: =IFERROR(AVERAGEIFS(Tareas!$E$6:$E$45,Tareas!$A$6:$A$45,"P*",Tareas!$B$6:$B$45,"T2"),"")
A7: T3 · Crea un correo pendiente en Correos y archivos y lo completa | B7: =COUNTIFS(Tareas!$A$6:$A$45,"P*",Tareas!$B$6:$B$45,"T3",Tareas!$D$6:$D$45,"?*") -> 0 | C7: =COUNTIFS(Tareas!$A$6:$A$45,"P*",Tareas!$B$6:$B$45,"T3",Tareas!$D$6:$D$45,"Éxito") -> 0 | D7: =IF(B7=0,"",C7/B7) | E7: =IF(B7=0,"",IF(D7>=0.8,"Sí","No")) | F7: =IFERROR(AVERAGEIFS(Tareas!$E$6:$E$45,Tareas!$A$6:$A$45,"P*",Tareas!$B$6:$B$45,"T3"),"")
A8: T4 · Completa una tarea y llega a la pantalla de racha con Lumi encendida | B8: =COUNTIFS(Tareas!$A$6:$A$45,"P*",Tareas!$B$6:$B$45,"T4",Tareas!$D$6:$D$45,"?*") -> 0 | C8: =COUNTIFS(Tareas!$A$6:$A$45,"P*",Tareas!$B$6:$B$45,"T4",Tareas!$D$6:$D$45,"Éxito") -> 0 | D8: =IF(B8=0,"",C8/B8) | E8: =IF(B8=0,"",IF(D8>=0.8,"Sí","No")) | F8: =IFERROR(AVERAGEIFS(Tareas!$E$6:$E$45,Tareas!$A$6:$A$45,"P*",Tareas!$B$6:$B$45,"T4"),"")
A9: T5 · Se cumple el criterio de terminado del update U01 o U02 | B9: =COUNTIFS(Tareas!$A$6:$A$45,"P*",Tareas!$B$6:$B$45,"T5",Tareas!$D$6:$D$45,"?*") -> 0 | C9: =COUNTIFS(Tareas!$A$6:$A$45,"P*",Tareas!$B$6:$B$45,"T5",Tareas!$D$6:$D$45,"Éxito") -> 0 | D9: =IF(B9=0,"",C9/B9) | E9: =IF(B9=0,"",IF(D9>=0.8,"Sí","No")) | F9: =IFERROR(AVERAGEIFS(Tareas!$E$6:$E$45,Tareas!$A$6:$A$45,"P*",Tareas!$B$6:$B$45,"T5"),"")
A11: Indicador | B11: Valor
A12: Participantes registrados | B12: =COUNTIFS(Participantes!$A$6:$A$13,"P*",Participantes!$B$6:$B$13,"?*") -> 0
A13: Participantes elegibles | B13: =COUNTIFS(Participantes!$A$6:$A$13,"P*",Participantes!$E$6:$E$13,"Sí") -> 0
A14: Participantes no elegibles (deben salir) | B14: =COUNTIFS(Participantes!$A$6:$A$13,"P*",Participantes!$E$6:$E$13,"No") -> 0
A15: Consentimientos grabados | B15: =COUNTIFS(Participantes!$A$6:$A$13,"P*",Participantes!$J$6:$J$13,"Sí") -> 0
A16: SUS completos | B16: =COUNTIFS(SUS!$A$6:$A$13,"P*",SUS!$L$6:$L$13,">=0") -> 0
A17: SUS promedio | B17: =IFERROR(AVERAGEIFS(SUS!$L$6:$L$13,SUS!$A$6:$A$13,"P*"),"")
A18: SUS mínimo | B18: =IF(B16=0,"",_xlfn.MINIFS(SUS!$L$6:$L$13,SUS!$A$6:$A$13,"P*"))
A19: SUS máximo | B19: =IF(B16=0,"",_xlfn.MAXIFS(SUS!$L$6:$L$13,SUS!$A$6:$A$13,"P*"))
A20: Interpretación del SUS | B20: =IF(B17="","",IF(B17<51,"Problemas serios",IF(B17<68,"Por debajo del promedio (68)",IF(B17<=80,"Aceptable","Excelente"))))
A21: Tareas que cumplen ≥ 80 % | B21: =COUNTIF(E5:E9,"Sí")&" de 5" -> 0 de 5
A22: Hallazgos registrados | B22: =COUNTIFS(Hallazgos!$A$6:$A$15,"H*",Hallazgos!$B$6:$B$15,"?*") -> 0
A23: Hallazgos críticos o graves | B23: =COUNTIFS(Hallazgos!$B$6:$B$15,"?*",Hallazgos!$G$6:$G$15,">=3") -> 0
A24: Hallazgos con update que los responde | B24: =COUNTIFS(Hallazgos!$B$6:$B$15,"?*",Hallazgos!$J$6:$J$15,"?*") -> 0
A26: ¿Release validado? | B26: =IF(OR(B13<5,B16<5),"Faltan participantes",IF(AND(COUNTIF(E5:E9,"Sí")=5,B17>=68),"Sí","No")) -> Faltan participantes
A27: Criterio: 5 o más participantes elegibles con SUS completo, cada tarea ≥ 80 % y SUS promedio ≥ 68.

Sheet Participantes
A1: Participantes
A2: Una fila por participante. Elegible = no es compañero, familiar ni amigo de nadie del equipo y cumple el perfil.
A4: Código | B4: Cargo / perfil | C4: Tamaño empresa (empleados) | D4: Fuente de contacto | E4: Elegible | F4: Modalidad | G4: Fecha | H4: Moderador | I4: Observador QA | J4: Consentimiento grabado | K4: Celular y navegador | L4: Versión probada | M4: Enlace a evidencia (carpeta del equipo)
A5: Ejemplo | B5: Auxiliar administrativa | C5: 80 | D5: Contacto CBA Ingenieros | E5: Sí | F5: Videollamada | G5: 25/10/2026 | H5: Alejandro Macías | I5: Samuel Montealegre | J5: Sí | K5: Android · Chrome | L5: v0.2 (URL fija) | M5: Drive/Validacion_R1/Ejemplo
A6: P01
A7: P02
A8: P03
A9: P04
A10: P05
A11: P06
A12: P07
A13: P08

Sheet Tareas
A1: Resultados por tarea
A2: Éxito = cumple el criterio sin ayuda. Bloqueo de más de 3 minutos = Fracaso. Completar fuera de tiempo = Fracaso.
A4: Participante | B4: Tarea | C4: Criterio de éxito | D4: Resultado | E4: Tiempo (s) | F4: Límite (s) | G4: Fuera de tiempo | H4: Errores observados | I4: Cita textual
A5: Ejemplo | B5: T4 | C5: Completa una tarea y llega a la pantalla de racha con Lumi encendida | D5: Fracaso | E5: 75 | F5: 45 | G5: =IF(AND(ISNUMBER(E5),ISNUMBER(F5)),IF(E5>F5,"Sí","No"),"") -> Sí | H5: Completó la tarea pero buscó a Lumi en Perfil | I5: «¿Dónde está la mascota?»
A6: P01 | B6: T1 | C6: Crea el espacio y una tarea asociada; al recargar, ambos siguen ahí | F6: 120 | G6: =IF(AND(ISNUMBER(E6),ISNUMBER(F6)),IF(E6>F6,"Sí","No"),"")
A7: P01 | B7: T2 | C7: Elige una mesa, coloca al menos dos tarjetas con nombre y guarda | F7: 180 | G7: =IF(AND(ISNUMBER(E7),ISNUMBER(F7)),IF(E7>F7,"Sí","No"),"")
A8: P01 | B8: T3 | C8: Crea un correo pendiente en Correos y archivos y lo completa | F8: 60 | G8: =IF(AND(ISNUMBER(E8),ISNUMBER(F8)),IF(E8>F8,"Sí","No"),"")
A9: P01 | B9: T4 | C9: Completa una tarea y llega a la pantalla de racha con Lumi encendida | F9: 45 | G9: =IF(AND(ISNUMBER(E9),ISNUMBER(F9)),IF(E9>F9,"Sí","No"),"")
A10: P01 | B10: T5 | C10: Se cumple el criterio de terminado del update U01 o U02 | G10: =IF(AND(ISNUMBER(E10),ISNUMBER(F10)),IF(E10>F10,"Sí","No"),"")
A11: P02 | B11: T1 | C11: Crea el espacio y una tarea asociada; al recargar, ambos siguen ahí | F11: 120 | G11: =IF(AND(ISNUMBER(E11),ISNUMBER(F11)),IF(E11>F11,"Sí","No"),"")
A12: P02 | B12: T2 | C12: Elige una mesa, coloca al menos dos tarjetas con nombre y guarda | F12: 180 | G12: =IF(AND(ISNUMBER(E12),ISNUMBER(F12)),IF(E12>F12,"Sí","No"),"")
A13: P02 | B13: T3 | C13: Crea un correo pendiente en Correos y archivos y lo completa | F13: 60 | G13: =IF(AND(ISNUMBER(E13),ISNUMBER(F13)),IF(E13>F13,"Sí","No"),"")
A14: P02 | B14: T4 | C14: Completa una tarea y llega a la pantalla de racha con Lumi encendida | F14: 45 | G14: =IF(AND(ISNUMBER(E14),ISNUMBER(F14)),IF(E14>F14,"Sí","No"),"")
A15: P02 | B15: T5 | C15: Se cumple el criterio de terminado del update U01 o U02 | G15: =IF(AND(ISNUMBER(E15),ISNUMBER(F15)),IF(E15>F15,"Sí","No"),"")
A16: P03 | B16: T1 | C16: Crea el espacio y una tarea asociada; al recargar, ambos siguen ahí | F16: 120 | G16: =IF(AND(ISNUMBER(E16),ISNUMBER(F16)),IF(E16>F16,"Sí","No"),"")
A17: P03 | B17: T2 | C17: Elige una mesa, coloca al menos dos tarjetas con nombre y guarda | F17: 180 | G17: =IF(AND(ISNUMBER(E17),ISNUMBER(F17)),IF(E17>F17,"Sí","No"),"")
A18: P03 | B18: T3 | C18: Crea un correo pendiente en Correos y archivos y lo completa | F18: 60 | G18: =IF(AND(ISNUMBER(E18),ISNUMBER(F18)),IF(E18>F18,"Sí","No"),"")
A19: P03 | B19: T4 | C19: Completa una tarea y llega a la pantalla de racha con Lumi encendida | F19: 45 | G19: =IF(AND(ISNUMBER(E19),ISNUMBER(F19)),IF(E19>F19,"Sí","No"),"")
A20: P03 | B20: T5 | C20: Se cumple el criterio de terminado del update U01 o U02 | G20: =IF(AND(ISNUMBER(E20),ISNUMBER(F20)),IF(E20>F20,"Sí","No"),"")
A21: P04 | B21: T1 | C21: Crea el espacio y una tarea asociada; al recargar, ambos siguen ahí | F21: 120 | G21: =IF(AND(ISNUMBER(E21),ISNUMBER(F21)),IF(E21>F21,"Sí","No"),"")
A22: P04 | B22: T2 | C22: Elige una mesa, coloca al menos dos tarjetas con nombre y guarda | F22: 180 | G22: =IF(AND(ISNUMBER(E22),ISNUMBER(F22)),IF(E22>F22,"Sí","No"),"")
A23: P04 | B23: T3 | C23: Crea un correo pendiente en Correos y archivos y lo completa | F23: 60 | G23: =IF(AND(ISNUMBER(E23),ISNUMBER(F23)),IF(E23>F23,"Sí","No"),"")
A24: P04 | B24: T4 | C24: Completa una tarea y llega a la pantalla de racha con Lumi encendida | F24: 45 | G24: =IF(AND(ISNUMBER(E24),ISNUMBER(F24)),IF(E24>F24,"Sí","No"),"")
A25: P04 | B25: T5 | C25: Se cumple el criterio de terminado del update U01 o U02 | G25: =IF(AND(ISNUMBER(E25),ISNUMBER(F25)),IF(E25>F25,"Sí","No"),"")
A26: P05 | B26: T1 | C26: Crea el espacio y una tarea asociada; al recargar, ambos siguen ahí | F26: 120 | G26: =IF(AND(ISNUMBER(E26),ISNUMBER(F26)),IF(E26>F26,"Sí","No"),"")
A27: P05 | B27: T2 | C27: Elige una mesa, coloca al menos dos tarjetas con nombre y guarda | F27: 180 | G27: =IF(AND(ISNUMBER(E27),ISNUMBER(F27)),IF(E27>F27,"Sí","No"),"")
A28: P05 | B28: T3 | C28: Crea un correo pendiente en Correos y archivos y lo completa | F28: 60 | G28: =IF(AND(ISNUMBER(E28),ISNUMBER(F28)),IF(E28>F28,"Sí","No"),"")
A29: P05 | B29: T4 | C29: Completa una tarea y llega a la pantalla de racha con Lumi encendida | F29: 45 | G29: =IF(AND(ISNUMBER(E29),ISNUMBER(F29)),IF(E29>F29,"Sí","No"),"")
A30: P05 | B30: T5 | C30: Se cumple el criterio de terminado del update U01 o U02 | G30: =IF(AND(ISNUMBER(E30),ISNUMBER(F30)),IF(E30>F30,"Sí","No"),"")
A31: P06 | B31: T1 | C31: Crea el espacio y una tarea asociada; al recargar, ambos siguen ahí | F31: 120 | G31: =IF(AND(ISNUMBER(E31),ISNUMBER(F31)),IF(E31>F31,"Sí","No"),"")
A32: P06 | B32: T2 | C32: Elige una mesa, coloca al menos dos tarjetas con nombre y guarda | F32: 180 | G32: =IF(AND(ISNUMBER(E32),ISNUMBER(F32)),IF(E32>F32,"Sí","No"),"")
A33: P06 | B33: T3 | C33: Crea un correo pendiente en Correos y archivos y lo completa | F33: 60 | G33: =IF(AND(ISNUMBER(E33),ISNUMBER(F33)),IF(E33>F33,"Sí","No"),"")
A34: P06 | B34: T4 | C34: Completa una tarea y llega a la pantalla de racha con Lumi encendida | F34: 45 | G34: =IF(AND(ISNUMBER(E34),ISNUMBER(F34)),IF(E34>F34,"Sí","No"),"")
A35: P06 | B35: T5 | C35: Se cumple el criterio de terminado del update U01 o U02 | G35: =IF(AND(ISNUMBER(E35),ISNUMBER(F35)),IF(E35>F35,"Sí","No"),"")
A36: P07 | B36: T1 | C36: Crea el espacio y una tarea asociada; al recargar, ambos siguen ahí | F36: 120 | G36: =IF(AND(ISNUMBER(E36),ISNUMBER(F36)),IF(E36>F36,"Sí","No"),"")
A37: P07 | B37: T2 | C37: Elige una mesa, coloca al menos dos tarjetas con nombre y guarda | F37: 180 | G37: =IF(AND(ISNUMBER(E37),ISNUMBER(F37)),IF(E37>F37,"Sí","No"),"")
A38: P07 | B38: T3 | C38: Crea un correo pendiente en Correos y archivos y lo completa | F38: 60 | G38: =IF(AND(ISNUMBER(E38),ISNUMBER(F38)),IF(E38>F38,"Sí","No"),"")
A39: P07 | B39: T4 | C39: Completa una tarea y llega a la pantalla de racha con Lumi encendida | F39: 45 | G39: =IF(AND(ISNUMBER(E39),ISNUMBER(F39)),IF(E39>F39,"Sí","No"),"")
A40: P07 | B40: T5 | C40: Se cumple el criterio de terminado del update U01 o U02 | G40: =IF(AND(ISNUMBER(E40),ISNUMBER(F40)),IF(E40>F40,"Sí","No"),"")
A41: P08 | B41: T1 | C41: Crea el espacio y una tarea asociada; al recargar, ambos siguen ahí | F41: 120 | G41: =IF(AND(ISNUMBER(E41),ISNUMBER(F41)),IF(E41>F41,"Sí","No"),"")
...

Sheet SUS
A1: Cuestionario SUS
A2: Calificaciones de 1 a 5. El puntaje aparece cuando las diez respuestas están completas.
A4: Participante | B4: Q1 | C4: Q2 | D4: Q3 | E4: Q4 | F4: Q5 | G4: Q6 | H4: Q7 | I4: Q8 | J4: Q9 | K4: Q10 | L4: Puntaje SUS | M4: ¿Qué fue lo más difícil? | N4: ¿Qué le haría volver a usarla mañana?
A5: Ejemplo | B5: 4 | C5: 2 | D5: 4 | E5: 1 | F5: 4 | G5: 2 | H5: 5 | I5: 2 | J5: 4 | K5: 1 | L5: =IF(COUNT(B5:K5)=10,((B5+D5+F5+H5+J5)-5+(25-(C5+E5+G5+I5+K5)))*2.5,"") -> 82.5 | M5: Encontrar dónde se ve el récord | N5: Que me recuerde a la hora de salida
A6: P01 | L6: =IF(COUNT(B6:K6)=10,((B6+D6+F6+H6+J6)-5+(25-(C6+E6+G6+I6+K6)))*2.5,"")
A7: P02 | L7: =IF(COUNT(B7:K7)=10,((B7+D7+F7+H7+J7)-5+(25-(C7+E7+G7+I7+K7)))*2.5,"")
A8: P03 | L8: =IF(COUNT(B8:K8)=10,((B8+D8+F8+H8+J8)-5+(25-(C8+E8+G8+I8+K8)))*2.5,"")
A9: P04 | L9: =IF(COUNT(B9:K9)=10,((B9+D9+F9+H9+J9)-5+(25-(C9+E9+G9+I9+K9)))*2.5,"")
A10: P05 | L10: =IF(COUNT(B10:K10)=10,((B10+D10+F10+H10+J10)-5+(25-(C10+E10+G10+I10+K10)))*2.5,"")
A11: P06 | L11: =IF(COUNT(B11:K11)=10,((B11+D11+F11+H11+J11)-5+(25-(C11+E11+G11+I11+K11)))*2.5,"")
A12: P07 | L12: =IF(COUNT(B12:K12)=10,((B12+D12+F12+H12+J12)-5+(25-(C12+E12+G12+I12+K12)))*2.5,"")
A13: P08 | L13: =IF(COUNT(B13:K13)=10,((B13+D13+F13+H13+J13)-5+(25-(C13+E13+G13+I13+K13)))*2.5,"")
A15: Promedio | L15: =IFERROR(AVERAGEIFS(L6:L13,A6:A13,"P*"),"")

Sheet Hallazgos
A1: Hallazgos priorizados
A2: Ordenar por severidad (4 a 1) y luego por participantes afectados. Solo problemas observados con evidencia.
A4: ID | B4: Hallazgo (qué pasó) | C4: Tarea | D4: Participantes afectados | E4: Participantes evaluados | F4: Frecuencia | G4: Severidad (1–4) | H4: Nivel | I4: Evidencia (código y minuto) | J4: Update que lo responde | K4: Criterio de terminado del update
A5: Ejemplo | B5: No encontraron el filtro de tareas digitales; buscaron en Progreso | C5: T4 | D5: 3 | E5: 5 | F5: =IF(AND(ISNUMBER(D5),ISNUMBER(E5)),D5&" de "&E5,"") -> 3 de 5 | G5: 3 | H5: =IF(G5=4,"Crítico",IF(G5=3,"Grave",IF(G5=2,"Moderado",IF(G5=1,"Menor","")))) -> Grave | I5: P02 min 6:10; P04 min 7:45; P05 min 5:30 | J5: Update 0X | K5: Desde Inicio, el usuario filtra sus tareas digitales en menos de 20 s
A6: H1 | E6: =COUNTIFS(Participantes!$A$6:$A$13,"P*",Participantes!$E$6:$E$13,"Sí") -> 0 | F6: =IF(AND(ISNUMBER(D6),ISNUMBER(E6)),D6&" de "&E6,"") | H6: =IF(G6=4,"Crítico",IF(G6=3,"Grave",IF(G6=2,"Moderado",IF(G6=1,"Menor",""))))
A7: H2 | E7: =COUNTIFS(Participantes!$A$6:$A$13,"P*",Participantes!$E$6:$E$13,"Sí") -> 0 | F7: =IF(AND(ISNUMBER(D7),ISNUMBER(E7)),D7&" de "&E7,"") | H7: =IF(G7=4,"Crítico",IF(G7=3,"Grave",IF(G7=2,"Moderado",IF(G7=1,"Menor",""))))
A8: H3 | E8: =COUNTIFS(Participantes!$A$6:$A$13,"P*",Participantes!$E$6:$E$13,"Sí") -> 0 | F8: =IF(AND(ISNUMBER(D8),ISNUMBER(E8)),D8&" de "&E8,"") | H8: =IF(G8=4,"Crítico",IF(G8=3,"Grave",IF(G8=2,"Moderado",IF(G8=1,"Menor",""))))
A9: H4 | E9: =COUNTIFS(Participantes!$A$6:$A$13,"P*",Participantes!$E$6:$E$13,"Sí") -> 0 | F9: =IF(AND(ISNUMBER(D9),ISNUMBER(E9)),D9&" de "&E9,"") | H9: =IF(G9=4,"Crítico",IF(G9=3,"Grave",IF(G9=2,"Moderado",IF(G9=1,"Menor",""))))
A10: H5 | E10: =COUNTIFS(Participantes!$A$6:$A$13,"P*",Participantes!$E$6:$E$13,"Sí") -> 0 | F10: =IF(AND(ISNUMBER(D10),ISNUMBER(E10)),D10&" de "&E10,"") | H10: =IF(G10=4,"Crítico",IF(G10=3,"Grave",IF(G10=2,"Moderado",IF(G10=1,"Menor",""))))
A11: H6 | E11: =COUNTIFS(Participantes!$A$6:$A$13,"P*",Participantes!$E$6:$E$13,"Sí") -> 0 | F11: =IF(AND(ISNUMBER(D11),ISNUMBER(E11)),D11&" de "&E11,"") | H11: =IF(G11=4,"Crítico",IF(G11=3,"Grave",IF(G11=2,"Moderado",IF(G11=1,"Menor",""))))
A12: H7 | E12: =COUNTIFS(Participantes!$A$6:$A$13,"P*",Participantes!$E$6:$E$13,"Sí") -> 0 | F12: =IF(AND(ISNUMBER(D12),ISNUMBER(E12)),D12&" de "&E12,"") | H12: =IF(G12=4,"Crítico",IF(G12=3,"Grave",IF(G12=2,"Moderado",IF(G12=1,"Menor",""))))
A13: H8 | E13: =COUNTIFS(Participantes!$A$6:$A$13,"P*",Participantes!$E$6:$E$13,"Sí") -> 0 | F13: =IF(AND(ISNUMBER(D13),ISNUMBER(E13)),D13&" de "&E13,"") | H13: =IF(G13=4,"Crítico",IF(G13=3,"Grave",IF(G13=2,"Moderado",IF(G13=1,"Menor",""))))
A14: H9 | E14: =COUNTIFS(Participantes!$A$6:$A$13,"P*",Participantes!$E$6:$E$13,"Sí") -> 0 | F14: =IF(AND(ISNUMBER(D14),ISNUMBER(E14)),D14&" de "&E14,"") | H14: =IF(G14=4,"Crítico",IF(G14=3,"Grave",IF(G14=2,"Moderado",IF(G14=1,"Menor",""))))
A15: H10 | E15: =COUNTIFS(Participantes!$A$6:$A$13,"P*",Participantes!$E$6:$E$13,"Sí") -> 0 | F15: =IF(AND(ISNUMBER(D15),ISNUMBER(E15)),D15&" de "&E15,"") | H15: =IF(G15=4,"Crítico",IF(G15=3,"Grave",IF(G15=2,"Moderado",IF(G15=1,"Menor",""))))
